Workbook
Name _pto2: #REF!
Name CAPACITACION_A_PERSONAL: #REF!
Name concepto_gasto: #REF!
Name Conceptos: #REF!
Name conceptos_gastos: #REF!
Name pto: #REF!
Name puntodeventa: #REF!
Name puntosdeventa: #REF!
Name puntosventa: #REF!
Name puntoventa: #REF!
Name venta: #REF!
Name ventas: #REF!

Sheet FO-GFI-03 
P1: Código: FO-GFI-03
D2: PROGRAMACIÓN DE PAGOS | P2: Versión: 04
P3: Fecha: 29-Jul-21
A5: SEMANA DE PAGO: | C5: PROGRAMACIÓN DE PAGOS DEL 6 OCTUBRE 2023 | J5: TIPO DE PAGO: | L5: CONSIGNACIÓN | M5: EFECTIVO | N5: TRANSFERENCIA | O5: SEDE ADMINISTRATIVA | Q5: ZONA
A6: ITEM | B6: VALOR NETO A PAGAR | C6: No. De CT | D6: CT1 | E6: CT2 | F6: CT3 | G6: CT4 | H6: # CASO EN ITOP | I6: No. FACTURA Y/O CUENTA DE COBRO | J6: CONCEPTO | K6: OFICINA | L6: CC/ NIT | M6: BENEFICIARIO | N6: BANCO | O6: TIPO DE CUENTA | P6: CUENTA | Q6: OBSERVACIÓN | S6: DCTO CONTABLE
B7: =706753+880367 -> 1587120 | I7: FEWT3039-3038 | J7: 23359505 | K7: 23359505 | L7: 900933434 | M7: =VLOOKUP(L7,#REF!,2,0) -> #REF! | N7: =VLOOKUP(L7,#REF!,3,0) -> #REF! | O7: =VLOOKUP(L7,#REF!,4,0) -> #REF! | P7: =VLOOKUP(L7,#REF!,5,0) -> #REF! | Q7: Factura Fewt3039 Tiquete Viaje Ida Y Regreso Cali-guapi Al Colaborador Miguel Antonio Garcia (promotor Comercial De Timbiqui)- Factura Fewt3038 Tiquetes Ida Y Regreso Bogota - Presidente Ejecutivo Josue Laso Tacha | S7: DC01-16901-16900
B8: 1650165 | I8: CRG 252220 | J8: 23359505 | L8: 800115720 | M8: =VLOOKUP(L8,#REF!,2,0) -> #REF! | N8: =VLOOKUP(L8,#REF!,3,0) -> #REF! | O8: =VLOOKUP(L8,#REF!,4,0) -> #REF! | P8: =VLOOKUP(L8,#REF!,5,0) -> #REF! | Q8: Factura Crg 252220 Suministro De 45 Lamparas 60x60 Para Adecuaciones Locativas Solictud Area De Mantenimiento | S8: DC01-16855
B9: 1751416 | I9: FEV 1776 | J9: 23359505 | L9: 34609530 | M9: =VLOOKUP(L9,#REF!,2,0) -> #REF! | N9: =VLOOKUP(L9,#REF!,3,0) -> #REF! | O9: =VLOOKUP(L9,#REF!,4,0) -> #REF! | P9: =VLOOKUP(L9,#REF!,5,0) -> #REF! | Q9: Factura Fev 1776 Compra De Nevera Para La Zona De Cafeteria, Oficina San Agustin | S9: DC01-16802
B10: 1444600 | I10: FEV66 | J10: 23359505 | L10: 805028971 | M10: =VLOOKUP(L10,#REF!,2,0) -> #REF! | N10: =VLOOKUP(L10,#REF!,3,0) -> #REF! | O10: =VLOOKUP(L10,#REF!,4,0) -> #REF! | P10: =VLOOKUP(L10,#REF!,5,0) -> #REF! | Q10: Ocgg 001759 Fact Fev66 Jv Publicidad, Pasador De Billetes Bandejas En Acero Inoxidable Para Instalacion En Los Nuevos Puntos En La Zona De Popayan | S10: DC01-16819
B11: 3611500 | I11: FE1904 | J11: 23359505 | L11: 901095203 | M11: =VLOOKUP(L11,#REF!,2,0) -> #REF! | N11: =VLOOKUP(L11,#REF!,3,0) -> #REF! | O11: =VLOOKUP(L11,#REF!,4,0) -> #REF! | P11: =VLOOKUP(L11,#REF!,5,0) -> #REF! | Q11: Factura Fe1904, Suministro De 2 Puestos De Trabajo Doble Para La Oficina De Alchivo Reubicada En El Pv Vi?edo | S11: DC01-16903
B12: =190400+1274000+321300 -> 1785700 | I12: FVE182-183-184 | J12: 23359505 | L12: 1143939878 | M12: =VLOOKUP(L12,#REF!,2,0) -> #REF! | N12: =VLOOKUP(L12,#REF!,3,0) -> #REF! | O12: =VLOOKUP(L12,#REF!,4,0) -> #REF! | P12: =VLOOKUP(L12,#REF!,5,0) -> #REF! | Q12: Factura Fve 182 Impresion De Lona Para Backing Mas Instalacion Para Evento Fashion Weekend - Factura Fve 183 Elaboracion De Stand Con Vinilo Laminado Instalado Sobre Mdf Mas Letras En Noen Flez De 2.10x 3 - Factura Fve 184 Suministro De 300 Stikers Raspatodos Para Marcar Pendones En Popayan Solicitada Por El Area De Mercadeo | S12: DC01-16907-16906-16908
B13: 5750000 | I13: ZC 948 | J13: 23359505 | L13: 900218859 | M13: =VLOOKUP(L13,#REF!,2,0) -> #REF! | N13: =VLOOKUP(L13,#REF!,3,0) -> #REF! | O13: =VLOOKUP(L13,#REF!,4,0) -> #REF! | P13: =VLOOKUP(L13,#REF!,5,0) -> #REF! | Q13: Factura Zc 945 Correspondiente A Acuerdo Comercial Pauta Publicitaria Para Aniversario 15 A?os | S13: DC01-16897
B14: 550000 | I14: FEVE49 | J14: 23359505 | K14: 23 | L14: 34537020 | M14: =VLOOKUP(L14,#REF!,2,0) -> #REF! | N14: =VLOOKUP(L14,#REF!,3,0) -> #REF! | O14: =VLOOKUP(L14,#REF!,4,0) -> #REF! | P14: =VLOOKUP(L14,#REF!,5,0) -> #REF! | Q14: Factura Feve49 , Servicio De Parqueadero Para Los Vehiculos Asignados A La Zona Cso. Durante El Mes De Octubre | S14: DC01-16896
B15: 274453 | I15: EVP-3000 | J15: 23359505 | L15: 800185326 | M15: =VLOOKUP(L15,#REF!,2,0) -> #REF! | N15: =VLOOKUP(L15,#REF!,3,0) -> #REF! | O15: =VLOOKUP(L15,#REF!,4,0) -> #REF! | P15: =VLOOKUP(L15,#REF!,5,0) -> #REF! | Q15: Factura Evp-3000 Serrvicio De Mantenimiento Preventivo De Las Ups Que Se Encuentran En La Oficina Principal De San Agustin | S15: DC01-16904
B16: =351225+1107601 -> 1458826 | I16: 74928-74378 | J16: 23355002 | L16: 900677732 | M16: QI ENERGY | N16: PSE | O16: PSE | P16: PSE | Q16: Factura74928 Energy Energia Vital, Servicio De Energia Medidor 7038621 Of 303 Mes De Octubre De 2023 - Factura74378 Energy Energia Vital, Servicio De Energia Medidor 7025288 Of 3 Octubre De 2023 | S16: DC01-16893-16892
B17: 3719812 | I17: FPO-9810394 | J17: 23359505 | L17: 860039988 | M17: =VLOOKUP(L17,#REF!,2,0) -> #REF! | N17: =VLOOKUP(L17,#REF!,3,0) -> #REF! | O17: =VLOOKUP(L17,#REF!,4,0) -> #REF! | P17: =VLOOKUP(L17,#REF!,5,0) -> #REF! | Q17: Factura Fpo-9810394 Y Fpo-9810391 Liberty Seguros, Pago Polizas Grupo Vida Colectiva | S17: DC01-16858
B18: 825240 | I18: FE55896 | J18: 23359505 | L18: 900361602 | M18: =VLOOKUP(L18,#REF!,2,0) -> #REF! | N18: =VLOOKUP(L18,#REF!,3,0) -> #REF! | O18: =VLOOKUP(L18,#REF!,4,0) -> #REF! | P18: =VLOOKUP(L18,#REF!,5,0) -> #REF! | Q18: Factura Fe55896 Plan Profesional De Rastreo Satelital Para El Vehiculo De Placa Csq360 Mitsubishi Campero De La Empresa Renovacion Por 12 Meses | S18: DC01-16814
B19: 1575000 | I19: MONO-59 | J19: 23359505 | L19: 1061762331 | M19: =VLOOKUP(L19,#REF!,2,0) -> #REF! | N19: =VLOOKUP(L19,#REF!,3,0) -> #REF! | O19: =VLOOKUP(L19,#REF!,4,0) -> #REF! | P19: =VLOOKUP(L19,#REF!,5,0) -> #REF! | Q19: Factura Mono-59 Martin Felipe Arcos Osorio, Grabacion Video Institucional Mos, A Cargo Del Proveedor Mono Marketing | S19: DC01-16414
B20: 1145900 | I20: 5381559 | J20: 22050102 | L20: 890304049 | M20: =VLOOKUP(L20,#REF!,2,0) -> #REF! | N20: =VLOOKUP(L20,#REF!,3,0) -> #REF! | O20: =VLOOKUP(L20,#REF!,4,0) -> #REF! | P20: =VLOOKUP(L20,#REF!,5,0) -> #REF! | Q20: Fact 5381559 Arquidiocesis De Cali, Plan Exequial Septiembre 2023 | S20: DC01-16641
B21: 22892250 | I21: FE 1180 | J21: 23359505 | L21: 900375592 | M21: =VLOOKUP(L21,#REF!,2,0) -> #REF! | N21: =VLOOKUP(L21,#REF!,3,0) -> #REF! | O21: =VLOOKUP(L21,#REF!,4,0) -> #REF! | P21: =VLOOKUP(L21,#REF!,5,0) -> #REF! | Q21: Factura Fe 1180 Suministros De 3 Cajas Fuertes Especiales, 3 Cerradura Digital, Y 3 Teclados Sargent Para Distribuicion En Puerto Tejada, Santander Y Popayan | S21: DC01-16745
B22: 5392128 | I22: E 226 | J22: 23352502 | L22: 901002398 | M22: =VLOOKUP(L22,#REF!,2,0) -> #REF! | N22: =VLOOKUP(L22,#REF!,3,0) -> #REF! | O22: =VLOOKUP(L22,#REF!,4,0) -> #REF! | P22: =VLOOKUP(L22,#REF!,5,0) -> #REF! | Q22: Fact E 226 Abogados, Contrato Prestacion De Servicios Profesionales De Abogado Mes De Septiembre/ 2023 | S22: DC01-16919
B23: 8634537 | I23: 5001449918 | J23: 22050102 | L23: 860014923 | M23: =VLOOKUP(L23,#REF!,2,0) -> #REF! | N23: =VLOOKUP(L23,#REF!,3,0) -> #REF! | O23: =VLOOKUP(L23,#REF!,4,0) -> #REF! | P23: =VLOOKUP(L23,#REF!,5,0) -> #REF! | Q23: Factura 05001449918 Caracol, Pauta Radial Tropicana Popayan 106.1 Fm Mes De Septiembre De 2023 | S23: DC01-16569
B24: 939250 | I24: 1839 | J24: 23359505 | L24: 901174726 | M24: =VLOOKUP(L24,#REF!,2,0) -> #REF! | N24: =VLOOKUP(L24,#REF!,3,0) -> #REF! | O24: =VLOOKUP(L24,#REF!,4,0) -> #REF! | P24: =VLOOKUP(L24,#REF!,5,0) -> #REF! | Q24: Factura 1839, Servicio De Mantenimiento De Aires Acondicionados Oficina Principal | S24: DC01-16822
B25: =2609067+2934800 -> 5543867 | I25: QEP20643-20608 | J25: 23359505 | L25: 900174087 | M25: =VLOOKUP(L25,#REF!,2,0) -> #REF! | N25: =VLOOKUP(L25,#REF!,3,0) -> #REF! | O25: =VLOOKUP(L25,#REF!,4,0) -> #REF! | P25: =VLOOKUP(L25,#REF!,5,0) -> #REF! | Q25: Factura Qep 20643 Quality Colombia Sa, Por Concepto De Licencia Servidor Manager Erp Administrativa Correspondiente Al Mes De Septiembre 2023 -Factura Qep 20608 Quality, Poliza Tipo B Correspondiente Al Mes De Septiembre 2023 | S25: DC01-16520-16521
B26: =308798+2188497 -> 2497295 | I26: FCE 6025-FE 162645 | J26: 23359505 | L26: 800049104 | M26: =VLOOKUP(L26,#REF!,2,0) -> #REF! | N26: =VLOOKUP(L26,#REF!,3,0) -> #REF! | O26: =VLOOKUP(L26,#REF!,4,0) -> #REF! | P26: =VLOOKUP(L26,#REF!,5,0) -> #REF! | Q26: Facturas Fce 6025 Por Concepto De Pruebas De Ingreso Y Evaluacion Medica Post Incapacidad (colaboradora Simplicia Monta?o) - Facturas Fe 162645 Por Concepto De Pruebas De Ingreso Y Egreso Al Personal De La Empresa Segun Relacion Adjunta | S26: DC01-16639-16638
B27: 463450 | I27: FE 9232 | J27: 23359505 | L27: 900297803 | M27: =VLOOKUP(L27,#REF!,2,0) -> #REF! | N27: =VLOOKUP(L27,#REF!,3,0) -> #REF! | O27: =VLOOKUP(L27,#REF!,4,0) -> #REF! | P27: =VLOOKUP(L27,#REF!,5,0) -> #REF! | Q27: Factura Fe 9232 Data Digital, Alquiler De Impresora Ubicadas En Miranda Y Oficina Ppal De Puerto Y Tejada Mes Agosto | S27: DC01-16646
B28: 3552085 | I28: FEV 3768 | J28: 23359505 | L28: 900950832 | M28: =VLOOKUP(L28,#REF!,2,0) -> #REF! | N28: =VLOOKUP(L28,#REF!,3,0) -> #REF! | O28: =VLOOKUP(L28,#REF!,4,0) -> #REF! | P28: =VLOOKUP(L28,#REF!,5,0) -> #REF! | Q28: Fact Fev 3768 Compra De Habladores Y Stickers De Baloto Para Publicidad En Puntos De Venta Solicitud Del Area De Mercadeo | S28: DC01-16820
B29: 2956677 | I29: FDT 15263 | J29: 23359505 | L29: 817000499 | M29: =VLOOKUP(L29,#REF!,2,0) -> #REF! | N29: =VLOOKUP(L29,#REF!,3,0) -> #REF! | O29: =VLOOKUP(L29,#REF!,4,0) -> #REF! | P29: =VLOOKUP(L29,#REF!,5,0) -> #REF! | Q29: Ocgg 1705 Factura Fdt 15263 Suministro De 14 Cajas De Rollos Papel Bond 57 X 20 | S29: DC01-16737
B30: 232364 | I30: FELE 29176 | J30: 23359505 | L30: 800169376 | M30: =VLOOKUP(L30,#REF!,2,0) -> #REF! | N30: =VLOOKUP(L30,#REF!,3,0) -> #REF! | O30: =VLOOKUP(L30,#REF!,4,0) -> #REF! | P30: =VLOOKUP(L30,#REF!,5,0) -> #REF! | Q30: Factura Fele 29176 Servicio De Vigilancia Monitoreo De Alarmas Hasta 32 Zonas/ Mes De Septiembre 2023 | S30: DC01-16750
B31: 1103856 | I31: RI30691 | J31: 23359505 | L31: 900352786 | M31: =VLOOKUP(L31,#REF!,2,0) -> #REF! | N31: =VLOOKUP(L31,#REF!,3,0) -> #REF! | O31: =VLOOKUP(L31,#REF!,4,0) -> #REF! | P31: =VLOOKUP(L31,#REF!,5,0) -> #REF! | Q31: Factura Mensual Ri30691 Risks, De Acuerdo Al Contrato Adjunto, De La Nueva Plataforma De Riesgos Para La Consulta De Terceros Mes De Septiembre 2023 | S31: DC01-16640
B32: 1226712 | I32: 267222 | J32: 23359505 | L32: 805030163 | M32: =VLOOKUP(L32,#REF!,2,0) -> #REF! | N32: =VLOOKUP(L32,#REF!,3,0) -> #REF! | O32: =VLOOKUP(L32,#REF!,4,0) -> #REF! | P32: =VLOOKUP(L32,#REF!,5,0) -> #REF! | Q32: Factura 26722 Compra De Materiales Para La Fabricacion Por Parter Dek Area De Mantenimiento De Dos Bicicleteros | S32: DC01-16648
B33: 675000 | J33: 23359505 | L33: 1061793315 | M33: =VLOOKUP(L33,#REF!,2,0) -> #REF! | N33: =VLOOKUP(L33,#REF!,3,0) -> #REF! | O33: =VLOOKUP(L33,#REF!,4,0) -> #REF! | P33: =VLOOKUP(L33,#REF!,5,0) -> #REF! | Q33: anticipo del 50% mantenimiento a 3 modulos tipo 2 de las zonas de santander, popayan y puerto | S33: 1000-4618
B34: 25526983 | J34: 23359505 | L34: 891300382 | M34: =VLOOKUP(L34,#REF!,2,0) -> #REF! | N34: =VLOOKUP(L34,#REF!,3,0) -> #REF! | O34: =VLOOKUP(L34,#REF!,4,0) -> #REF! | P34: =VLOOKUP(L34,#REF!,5,0) -> #REF! | Q34: Anticipo Del 30% (total Contrato $85.089.942) Para El Proveedor Harinera Del Valle Correspondiente A Anchetas Fin De A?o Previamente Aprobado Por Gerencia Y Direccion Financiera | S34: 1000-4621
B35: 14536900 | J35: 23359505 | L35: 800156716 | M35: =VLOOKUP(L35,#REF!,2,0) -> #REF! | N35: =VLOOKUP(L35,#REF!,3,0) -> #REF! | O35: =VLOOKUP(L35,#REF!,4,0) -> #REF! | P35: =VLOOKUP(L35,#REF!,5,0) -> #REF! | Q35: Anticipo Del 50% (total Contrato $29.073.800) Para El Proveedor Promma Comunicaciones Correspondiente A Anchetas Fin De A?o Previamente Aprobado Por Gerencia Y Direccion Financiera | S35: 100-4622
B36: 400000 | I36: 26 | J36: 23359505 | L36: 38287506 | M36: =VLOOKUP(L36,#REF!,2,0) -> #REF! | N36: =VLOOKUP(L36,#REF!,3,0) -> #REF! | O36: =VLOOKUP(L36,#REF!,4,0) -> #REF! | P36: =VLOOKUP(L36,#REF!,5,0) -> #REF! | Q36: Cuenta de cobro 26 fumigacion de 14 oficinas y compra de 5 productos quimicos de periferia y capacitacion al personal de sst | S36: DSEF- 1684
B37: =160000+160000 -> 320000 | J37: 23359505 | L37: 10128823 | M37: =VLOOKUP(L37,#REF!,2,0) -> #REF! | N37: =VLOOKUP(L37,#REF!,3,0) -> #REF! | O37: =VLOOKUP(L37,#REF!,4,0) -> #REF! | P37: =VLOOKUP(L37,#REF!,5,0) -> #REF! | Q37: Servcicio de transporte de 5 plantas electricas desde puerto tejada hasta a la oficina de santander para cubrir contingencia en el municipio - servicio de trasnporte de 5 plantas electricas al municipio de puerto tejada | S37: DSEF-1695 y DSEF -1738
B38: =235000+357200 -> 592200 | J38: 23359505 | L38: 1061795086 | M38: =VLOOKUP(L38,#REF!,2,0) -> #REF! | N38: =VLOOKUP(L38,#REF!,3,0) -> #REF! | O38: =VLOOKUP(L38,#REF!,4,0) -> #REF! | P38: =VLOOKUP(L38,#REF!,5,0) -> #REF! | Q38: Cuenta de cobro por concepto de 6 cuñas y perifoneo de productos y servicios- cuenta de cobro por cuñas radiales pauta publicitaria emisora el sol y occidente durante el mes de septiembre | S38: DSEF-1708 y DSEF-1732
B39: 130000 | J39: 23359505 | L39: 34326739 | M39: =VLOOKUP(L39,#REF!,2,0) -> #REF! | N39: =VLOOKUP(L39,#REF!,3,0) -> #REF! | O39: =VLOOKUP(L39,#REF!,4,0) -> #REF! | P39: =VLOOKUP(L39,#REF!,5,0) -> #REF! | Q39: cuenta de cobro de servicio de transporte de tubo galvanizado el dia 26 de seoptiembre, transporte de materiales sobrasntes desde pv san martin el dia 29 de septiembre, transport de parasol desde pv san eduardo 30 de septiembre | S39: DSEF-1714
B40: 451200 | I40: LF003/2023 | J40: 23359505 | L40: 10298579 | M40: =VLOOKUP(L40,#REF!,2,0) -> #REF! | N40: =VLOOKUP(L40,#REF!,3,0) -> #REF! | O40: =VLOOKUP(L40,#REF!,4,0) -> #REF! | P40: =VLOOKUP(L40,#REF!,5,0) -> #REF! | Q40: Cuenta de cobro LF003/2023 por servicio de mantenimiento general de planta electrica prinicpal oficina acertemos popayan cambio de insumos consumibles | S40: DSEF-1715
B41: =820000+719500 -> 1539500 | I41: 3 Y 4 | J41: 23359505 | L41: 1144028273 | M41: =VLOOKUP(L41,#REF!,2,0) -> #REF! | N41: =VLOOKUP(L41,#REF!,3,0) -> #REF! | O41: =VLOOKUP(L41,#REF!,4,0) -> #REF! | P41: =VLOOKUP(L41,#REF!,5,0) -> #REF! | Q41: cuenta de cobro 3, concepto de 50 refrigerios de santander celebracion del amor y amistad septiembre / Cuenta de cobro 4 cumpleaños mes septiembre por concepto de 38 refirgerios en la oficina de santander y 44 en la oficina de puerto tejada | S41: DSEF-1710 y DSEF 1726
...

Sheet consolidado
C1: GESTIÓN FINANCIERA | I1: Código: FO-GFI-03
C2: PROGRAMACIÓN DE PAGOS FACTURAS DE INTERNET | I2: Versión: 6
I3: Fecha: 29-Ago-24
A5: SEMANA DE PAGO: | C5: PROGRAMACIÓN DE PAGOS: DE 04 FEBRERO DE 2025 | F5: TIPO DE PAGO: | G5: CONSIGNACIÓN
A7: ITEM | B7: VALOR NETO A PAGAR | C7: No. FACTURA Y/O CUENTA DE COBRO | D7: CUENTA POR PAGAR | E7: CC/ NIT | F7: BENEFICIARIO | G7: BANCO | H7: TIPO DE CUENTA | I7: CUENTA | J7: OBSERVACIÓN | K7: DOCUMENTO CONTABLE
A8: =info!A2 -> 0 | B8: =info!B2 -> 0 | C8: =info!C2 -> 0 | D8: =info!D2 -> 0 | E8: =info!E2 -> 0 | F8: =info!F2 -> 0 | J8: =info!J2 -> 0 | K8: =info!K2 -> 0
A9: =info!A3 -> 0 | B9: =info!B3 -> 0 | C9: =info!C3 -> 0 | D9: =info!D3 -> 0 | E9: =info!E3 -> 0 | F9: =info!F3 -> 0 | J9: =info!J3 -> 0 | K9: =info!K3 -> 0
A10: =info!A4 -> 0 | B10: =info!B4 -> 0 | C10: =info!C4 -> 0 | D10: =info!D4 -> 0 | E10: =info!E4 -> 0 | F10: =info!F4 -> 0 | J10: =info!J4 -> 0 | K10: =info!K4 -> 0
A11: =info!A5 -> 0 | B11: =info!B5 -> 0 | C11: =info!C5 -> 0 | D11: =info!D5 -> 0 | E11: =info!E5 -> 0 | F11: =info!F5 -> 0 | J11: =info!J5 -> 0 | K11: =info!K5 -> 0
A12: =info!A6 -> 0 | B12: =info!B6 -> 0 | C12: =info!C6 -> 0 | D12: =info!D6 -> 0 | E12: =info!E6 -> 0 | F12: =info!F6 -> 0 | J12: =info!J6 -> 0 | K12: =info!K6 -> 0
A13: =info!A7 -> 0 | B13: =info!B7 -> 0 | C13: =info!C7 -> 0 | D13: =info!D7 -> 0 | E13: =info!E7 -> 0 | F13: =info!F7 -> 0 | J13: =info!J7 -> 0 | K13: =info!K7 -> 0
A14: =info!A8 -> 0 | B14: =info!B8 -> 0 | C14: =info!C8 -> 0 | D14: =info!D8 -> 0 | E14: =info!E8 -> 0 | F14: =info!F8 -> 0 | J14: =info!J8 -> 0 | K14: =info!K8 -> 0
A15: =info!A9 -> 0 | B15: =info!B9 -> 0 | C15: =info!C9 -> 0 | D15: =info!D9 -> 0 | E15: =info!E9 -> 0 | F15: =info!F9 -> 0 | J15: =info!J9 -> 0 | K15: =info!K9 -> 0
A16: =info!A10 -> 0 | B16: =info!B10 -> 0 | C16: =info!C10 -> 0 | D16: =info!D10 -> 0 | E16: =info!E10 -> 0 | F16: =info!F10 -> 0 | J16: =info!J10 -> 0 | K16: =info!K10 -> 0
A17: =info!A11 -> 0 | B17: =info!B11 -> 0 | C17: =info!C11 -> 0 | D17: =info!D11 -> 0 | E17: =info!E11 -> 0 | F17: =info!F11 -> 0 | J17: =info!J11 -> 0 | K17: =info!K11 -> 0
A18: 11 | B18: =info!B12 -> 0 | C18: =info!C12 -> 0 | D18: =info!D12 -> 0 | E18: =info!E12 -> 0 | F18: =info!F12 -> 0 | J18: =info!J12 -> 0 | K18: =info!K12 -> 0
A19: 12 | B19: =info!B13 -> 0 | C19: =info!C13 -> 0 | D19: =info!D13 -> 0 | E19: =info!E13 -> 0 | F19: =info!F13 -> 0 | J19: =info!J13 -> 0 | K19: =info!K13 -> 0
A20: 13 | B20: =info!B14 -> 0 | C20: =info!C14 -> 0 | D20: =info!D14 -> 0 | E20: =info!E14 -> 0 | F20: =info!F14 -> 0 | J20: =info!J14 -> 0 | K20: =info!K14 -> 0
A21: 14 | B21: =info!B15 -> 0 | C21: =info!C15 -> 0 | D21: =info!D15 -> 0 | E21: =info!E15 -> 0 | F21: =info!F15 -> 0 | J21: =info!J15 -> 0 | K21: =info!K15 -> 0
A22: 15 | B22: =info!B16 -> 0 | C22: =info!C16 -> 0 | D22: =info!D16 -> 0 | E22: =info!E16 -> 0 | F22: =info!F16 -> 0 | J22: =info!J16 -> 0 | K22: =info!K16 -> 0
A23: 16 | B23: =info!B17 -> 0 | C23: =info!C17 -> 0 | D23: =info!D17 -> 0 | E23: =info!E17 -> 0 | F23: =info!F17 -> 0 | J23: =info!J17 -> 0 | K23: =info!K17 -> 0
A24: 17 | B24: =info!B18 -> 0 | C24: =info!C18 -> 0 | D24: =info!D18 -> 0 | E24: =info!E18 -> 0 | F24: =info!F18 -> 0 | J24: =info!J18 -> 0 | K24: =info!K18 -> 0
A25: 18 | B25: =info!B19 -> 0 | C25: =info!C19 -> 0 | D25: =info!D19 -> 0 | E25: =info!E19 -> 0 | F25: =info!F19 -> 0 | J25: =info!J19 -> 0 | K25: =info!K19 -> 0
A26: 19 | B26: =info!B20 -> 0 | C26: =info!C20 -> 0 | D26: =info!D20 -> 0 | E26: =info!E20 -> 0 | F26: =info!F20 -> 0 | J26: =info!J20 -> 0 | K26: =info!K20 -> 0
A27: 20 | B27: =info!B21 -> 0 | C27: =info!C21 -> 0 | D27: =info!D21 -> 0 | E27: =info!E21 -> 0 | F27: =info!F21 -> 0 | J27: =info!J21 -> 0 | K27: =info!K21 -> 0
A28: 21 | B28: =info!B22 -> 0 | C28: =info!C22 -> 0 | D28: =info!D22 -> 0 | E28: =info!E22 -> 0 | F28: =info!F22 -> 0 | J28: =info!J22 -> 0 | K28: =info!K22 -> 0
A29: 22 | B29: =info!B23 -> 0 | C29: =info!C23 -> 0 | D29: =info!D23 -> 0 | E29: =info!E23 -> 0 | F29: =info!F23 -> 0 | J29: =info!J23 -> 0 | K29: =info!K23 -> 0
... A71: 49 | B71: =info!B65 -> 0 | C71: =info!C65 -> 0 | D71: =info!D65 -> 0 | E71: =info!E65 -> 0 | F71: =info!F65 -> 0 | J71: =info!J65 -> 0 | K71: =info!K65 -> 0
B72: =info!B66 -> 0 | C72: =info!C66 -> 0 | D72: =info!D66 -> 0 | E72: =info!E66 -> 0 | F72: =info!F66 -> 0 | J72: =info!J66 -> 0 | K72: =info!K66 -> 0
A73: 35 | B73: =info!B67 -> 0 | C73: =info!C67 -> 0 | D73: =info!D67 -> 0 | E73: =info!E67 -> 0 | F73: =info!F67 -> 0 | J73: =info!J67 -> 0 | K73: =info!K67 -> 0
B74: =SUM(B8:B73) -> 0
B76: ELABORA | E76: APRUEBA
B80: ________________________________________________________________________ | E80: ________________________________________________________________________
B81: FIRMA | E81: FIRMA

Sheet info
A1: ITEM | B1: VALOR NETO A PAGAR | C1: No. FACTURA Y/O CUENTA DE COBRO | D1: CUENTA POR PAGAR | E1: CC/ NIT | F1: BENEFICIARIO | G1: BANCO | H1: TIPO DE CUENTA | I1: CUENTA | J1: OBSERVACIÓN | K1: DOCUMENTO CONTABLE

Sheet REVISAR
P1: Código: FO-GFI-03
D2: PROGRAMACIÓN DE PAGOS | P2: Versión: 04
P3: Fecha: 29-Jul-21
A5: SEMANA DE PAGO: | C5: PROGRAMACIÓN DE PAGOS DEL 5 DE JULIO | J5: TIPO DE PAGO: | L5: CONSIGNACIÓN | M5: EFECTIVO | N5: TRANSFERENCIA | O5: SEDE ADMINISTRATIVA | Q5: ZONA
A6: ITEM | B6: VALOR NETO A PAGAR | C6: No. De CT | D6: CT1 | E6: CT2 | F6: CT3 | G6: CT4 | H6: # CASO EN ITOP | I6: No. FACTURA Y/O CUENTA DE COBRO | J6: CONCEPTO | K6: OFICINA | L6: CC/ NIT | M6: BENEFICIARIO | N6: BANCO | O6: TIPO DE CUENTA | P6: CUENTA | Q6: OBSERVACIÓN | S6: DCTO CONTABLE
B7: =3589197+654441 -> 4243638 | I7: Fept38790 | J7: 23359505 | L7: 830504013 | M7: =VLOOKUP(L7,#REF!,2,0) -> #REF! | N7: =VLOOKUP(L7,#REF!,3,0) -> #REF! | O7: =VLOOKUP(L7,#REF!,4,0) -> #REF! | P7: =VLOOKUP(L7,#REF!,5,0) -> #REF! | Q7: Factura Fept38790 Servicio Audiplay Mes De Junio /2024 Anticipo Al 50% Compra De Board Sunmi V2 Solicitud De Tecnologia | S7: DC01-19384-1000-5454
B8: 603800 | I8: Isso 10006 | J8: 23359505 | L8: 891500182 | M8: =VLOOKUP(L8,#REF!,2,0) -> #REF! | N8: =VLOOKUP(L8,#REF!,3,0) -> #REF! | O8: =VLOOKUP(L8,#REF!,4,0) -> #REF! | P8: =VLOOKUP(L8,#REF!,5,0) -> #REF! | Q8: Factura Isso 10006 Pruebas Al Personal Por Ingreso De Nuevos Colaboradores, De Acuerdo A La Relacion Adjunta | S8: DC01-19319
B9: 974709 | I9: Fv 7334 | J9: 23359505 | L9: 805019778 | M9: =VLOOKUP(L9,#REF!,2,0) -> #REF! | N9: =VLOOKUP(L9,#REF!,3,0) -> #REF! | O9: =VLOOKUP(L9,#REF!,4,0) -> #REF! | P9: =VLOOKUP(L9,#REF!,5,0) -> #REF! | Q9: Factura Fv 7334 Suministro De 3 Licencias De Microsoft Para Negocio 1 A?o (incluye Word, Excel, Powepoint, Outlook, Access, Publicher, 1tb One Drive, Para 1 Usuiario Con 6 Dispositivos) . | S9: DC01-19301
B10: =469200+533300 -> 1002500 | I10: Fedv 46491-45993 | J10: 23359505 | L10: 94062784 | M10: =VLOOKUP(L10,#REF!,2,0) -> #REF! | N10: =VLOOKUP(L10,#REF!,3,0) -> #REF! | O10: =VLOOKUP(L10,#REF!,4,0) -> #REF! | P10: =VLOOKUP(L10,#REF!,5,0) -> #REF! | Q10: Factura Fedv 46491 Compra De Tintas 664 Por Contingencia Para La Zona De Popay?n Solicitud ?rea Administrativa Factura Fedv 45993 Compra De 10 Teclados Y 10 Mouse Solicitud Del Area De Tecnologia | S10: DC01-19487-19323
B11: 5646921 | I11: Fe- 2462 | J11: 23359505 | L11: 901040914 | M11: =VLOOKUP(L11,#REF!,2,0) -> #REF! | N11: =VLOOKUP(L11,#REF!,3,0) -> #REF! | O11: =VLOOKUP(L11,#REF!,4,0) -> #REF! | P11: =VLOOKUP(L11,#REF!,5,0) -> #REF! | Q11: Factura Fe- 2462 Honorarios Con Ocasion De Servicios De Asesoria Legal Permanente En El Area Comercial, Civil Y Administrativo Al Mes De Junio 2024 | S11: DC01-19468
B12: =322000+230000 -> 552000 | I12: Fe 10954, Fe 10971 | J12: 23359505 | L12: 900297803 | M12: =VLOOKUP(L12,#REF!,2,0) -> #REF! | N12: =VLOOKUP(L12,#REF!,3,0) -> #REF! | O12: =VLOOKUP(L12,#REF!,4,0) -> #REF! | P12: =VLOOKUP(L12,#REF!,5,0) -> #REF! | Q12: Factura Fe 10954 Servicio De Alquiler Correspondiente Al Mes De Abril - Mayo Del 2024 Impresora En La Oficina De Area De Tecnologia De Santander Factura Fe 10971 Servicio De Alquiler Correspondiente Impresora En La Oficina De Area Financiera Santander | S12: DC01-19328-19339
B13: 1335006 | I13: Ade41194, Ade41189, Ade41195, Ade41193 | J13: 23359505 | L13: 890321156 | M13: =VLOOKUP(L13,#REF!,2,0) -> #REF! | N13: =VLOOKUP(L13,#REF!,3,0) -> #REF! | O13: =VLOOKUP(L13,#REF!,4,0) -> #REF! | P13: =VLOOKUP(L13,#REF!,5,0) -> #REF! | Q13: Factura Ade41194, Ade41189, Ade41195, Ade41193 Ciudadela Unicentro, Administracion Oficina, 304 D, 305b, 303-305 A Mes De Junio 2024 | S13: DC01-19546
B14: 114000 | I14: Fe 47850 | J14: 23359505 | L14: 830512127 | M14: =VLOOKUP(L14,#REF!,2,0) -> #REF! | N14: =VLOOKUP(L14,#REF!,3,0) -> #REF! | O14: =VLOOKUP(L14,#REF!,4,0) -> #REF! | P14: =VLOOKUP(L14,#REF!,5,0) -> #REF! | Q14: Factura Fe 47850 Centinela De Occidente, Servicio De Vigilancia Punto De Venta El Bosque Junio 2024 | S14: DC01-19613
B15: =764100+68000 -> 832100 | I15: Eoxi 10527-10673 | J15: 23359505 | L15: 901285199 | M15: =VLOOKUP(L15,#REF!,2,0) -> #REF! | N15: =VLOOKUP(L15,#REF!,3,0) -> #REF! | O15: =VLOOKUP(L15,#REF!,4,0) -> #REF! | P15: =VLOOKUP(L15,#REF!,5,0) -> #REF! | Q15: Factura Eoxi 10527 Compra De Taladro Para Personal De Mantenimiento Zona Santander Factura 10673 Recarga Y Mantenimiento A 4 Extintores Zona De Popay?n | S15: DC01-19330-19388
B16: 89000 | I16: 1137-7662 | J16: 23359505 | L16: 29598589 | M16: =VLOOKUP(L16,#REF!,2,0) -> #REF! | N16: =VLOOKUP(L16,#REF!,3,0) -> #REF! | O16: =VLOOKUP(L16,#REF!,4,0) -> #REF! | P16: =VLOOKUP(L16,#REF!,5,0) -> #REF! | Q16: Factura 1137-7662 Suministro De Abarzaderas Solicitud De Sistemas Para Trabajos En Occidente | S16: DC01-19492
B17: 191800 | I17: 1fe26059-20613 | J17: 23359505 | L17: 900968708 | M17: =VLOOKUP(L17,#REF!,2,0) -> #REF! | N17: =VLOOKUP(L17,#REF!,3,0) -> #REF! | O17: =VLOOKUP(L17,#REF!,4,0) -> #REF! | P17: =VLOOKUP(L17,#REF!,5,0) -> #REF! | Q17: Factura 1fe26059-20613 Suministro De Candados Requeridos Con Urgencia El D?a De Ayer Para El Pv Solidaridad Y El D?a De Hoy En El Pv Ulloa, Ambos De Popay?n. | S17: DC01-19347
B18: =6064448+6064448 -> 12128896 | I18: 01-1889663 01-1893250 | J18: 23359505 | L18: 890903910 | M18: =VLOOKUP(L18,#REF!,2,0) -> #REF! | N18: =VLOOKUP(L18,#REF!,3,0) -> #REF! | O18: =VLOOKUP(L18,#REF!,4,0) -> #REF! | P18: =VLOOKUP(L18,#REF!,5,0) -> #REF! | Q18: Factura 01-1889663 Radio Cadena Nacional, Cunas Radiales, Propaganda Progama Local Radio Uno Popayan, Noticias De Uno Popayan Recargas, Chances Y Pagos Abril/2024 Factura 01-1893250 Radio Cadena Nacional, Cunas Radiales, Propaganda Progama Local Radio Uno Popayan, Noticias De Uno Popayan Recargas, Chances Y Pagos Mayo/2024, | S18: DC01-19300-19486
B19: 2337221 | I19: Fe 2923 | J19: 23359505 | L19: 900123432 | M19: =VLOOKUP(L19,#REF!,2,0) -> #REF! | N19: =VLOOKUP(L19,#REF!,3,0) -> #REF! | O19: =VLOOKUP(L19,#REF!,4,0) -> #REF! | P19: =VLOOKUP(L19,#REF!,5,0) -> #REF! | Q19: Factura Fe 2923 Servicio Mensual De Aplicativo Binaps Software Service - Riesgos, Dctos, Planes De Accion, Auditorias, Pqrs Y Actas Junio/2024 | S19: DC01-19548
B20: 188020 | I20: Fe 83 | J20: 23359505 | L20: 901761523 | M20: =VLOOKUP(L20,'[1]CTAS BANCARIAS'!A:E,2,0) -> URBAN GROUP SOLUCIONES EMPRESARIALES | N20: =VLOOKUP(L20,#REF!,3,0) -> #REF! | O20: =VLOOKUP(L20,#REF!,4,0) -> #REF! | P20: =VLOOKUP(L20,#REF!,5,0) -> #REF! | Q20: Factura Fe 83 Servicio De Brandeo Ascensor Centro Comercial Terraplaza | S20: DC01-19556
B21: 5037300 | I21: Fve 2215 Y 2216 | J21: 23359505 | L21: 805021056 | M21: =VLOOKUP(L21,'[1]CTAS BANCARIAS'!A:E,2,0) -> TRANSPORTES ESPECIALES FLOR DEL VALLE | N21: =VLOOKUP(L21,#REF!,3,0) -> #REF! | O21: =VLOOKUP(L21,#REF!,4,0) -> #REF! | P21: =VLOOKUP(L21,#REF!,5,0) -> #REF! | Q21: Factura Fve 2215 Y 2216 Servicio De Transporte Ida Y Regreso Holguines Trade Center-parque Ppal Santander Junio 24,25,26,27,28 De2024 Y 2-3-4-5 De Julio | S21: DC01-19724
B22: 1481907 | I22: Fe 27673 | J22: 22050102 | L22: 900128172 | M22: =VLOOKUP(L22,'[1]CTAS BANCARIAS'!A:E,2,0) -> INDUSTRIAS L.H. S.A.S. | N22: =VLOOKUP(L22,#REF!,3,0) -> #REF! | O22: =VLOOKUP(L22,#REF!,4,0) -> #REF! | P22: =VLOOKUP(L22,#REF!,5,0) -> #REF! | Q22: Factura Fe 27673 Suministro De Cinta Impresora Erc | S22: DC01-19693
B23: 6867384 | I23: Ib 761 | J23: 22050102 | L23: 11335004 | M23: =VLOOKUP(L23,#REF!,2,0) -> #REF! | N23: =VLOOKUP(L23,#REF!,3,0) -> #REF! | O23: =VLOOKUP(L23,#REF!,4,0) -> #REF! | P23: =VLOOKUP(L23,#REF!,5,0) -> #REF! | Q23: Factura Ib 761 Factura Suministro De Cintas Tmu Erc 34-38 Para Todas Las Zonas 480popayan, 480 Stder, 480 Pto Tejada, 175 Occidente. Del 3 De Julio Al 3 De Septiembre | S23: DC01-19695
B24: 1997358 | I24: Fpo-11506584 | J24: 23359505 | L24: 860039988 | M24: =VLOOKUP(L24,#REF!,2,0) -> #REF! | N24: =VLOOKUP(L24,#REF!,3,0) -> #REF! | O24: =VLOOKUP(L24,#REF!,4,0) -> #REF! | P24: =VLOOKUP(L24,#REF!,5,0) -> #REF! | Q24: Factura Fpo-11506584 Liberty Seguros, Pago Polizas Por Concepto De Cobro De Prima Mensual Correspondiente Al Periodo 01/06/2024 Al 01/07/2024. Doc Cobro Inv-014344 | S24: DC01-19692
B25: =155000+79000 -> 234000 | I25: Fev 3366-3415 | J25: 23359505 | L25: 34609530 | M25: =VLOOKUP(L25,#REF!,2,0) -> #REF! | N25: =VLOOKUP(L25,#REF!,3,0) -> #REF! | O25: =VLOOKUP(L25,#REF!,4,0) -> #REF! | P25: =VLOOKUP(L25,#REF!,5,0) -> #REF! | Q25: Factura Fev 3366 Compra De Elementos De Prueba Para Aperturar Venta En La Casa De La Cultura Puerto Tejada (teclado Genius, Adaptador Display Sport Hdmi - Vga Factura Fev 3415 Compra De Una Base De Tv Para Aperturar Venta En Zona Puerto Tejada Solicitud De Gerencia | S25: DC01-19686-19676
B26: 180000 | I26: 421 | J26: 23359505 | L26: 900919176 | M26: =VLOOKUP(L26,#REF!,2,0) -> #REF! | N26: =VLOOKUP(L26,#REF!,3,0) -> #REF! | O26: =VLOOKUP(L26,#REF!,4,0) -> #REF! | P26: =VLOOKUP(L26,#REF!,5,0) -> #REF! | Q26: Factura 421 Visita Para Revisi?n Y Diagn?stico De Goteras Of De Puerto Tejada | S26: DC01-19687
B27: =552500+149500+138400 -> 840400 | I27: PPFE 727-706-802 | J27: 23359505 | L27: 10487194 | M27: =VLOOKUP(L27,#REF!,2,0) -> #REF! | N27: =VLOOKUP(L27,#REF!,3,0) -> #REF! | O27: =VLOOKUP(L27,#REF!,4,0) -> #REF! | P27: =VLOOKUP(L27,#REF!,5,0) -> #REF! | Q27: Factura Ppfe 727 Compra De Materiales Para Adecuaci?n En Pv San Antonio Miranda. Factura Ppfe 761 Compra De Materiales Para Asegurar Cabina De Venta Sector Puente Elevado De Santander Factura Ppfe 706 Compra De Lava Traperos Para Local Comercial Y Factura Ppfe 726 Y Compra De Chazos Y Pie De Amigos Para Instalar Aviso Luminoso En Pv La Trinidad Santander De Quilichao Factura Ppfe 802 Compra De Elementos Para Arreglo De Motobomba En La Oficina Principal De Santander | S27: DC01-19683-19670-19726
B28: 2316163 | I28: FELE 1567 | J28: 23359505 | L28: 817003377 | M28: =VLOOKUP(L28,#REF!,2,0) -> #REF! | N28: =VLOOKUP(L28,#REF!,3,0) -> #REF! | O28: =VLOOKUP(L28,#REF!,4,0) -> #REF! | P28: =VLOOKUP(L28,#REF!,5,0) -> #REF! | Q28: Factura Fele 1567 Solo Por Servicios S En C, Servicio Integral De Aseo Y Cafeteria De Lunes A Sabado 8 Horas Diurnas En La Zona De Puerto Tejada Mes De Junio De 2024 | S28: DC01-19684
B29: 120000 | I29: FC 2208 | J29: 23359505 | L29: 901562091 | M29: =VLOOKUP(L29,#REF!,2,0) -> #REF! | N29: =VLOOKUP(L29,#REF!,3,0) -> #REF! | O29: =VLOOKUP(L29,#REF!,4,0) -> #REF! | P29: =VLOOKUP(L29,#REF!,5,0) -> #REF! | Q29: Factura Fc 2208 Compra De Elementos De Prueba Para Aperturar Venta En La Casa De La Cultura Puerto Tejada (cable Hdmi, Mouse Genius, Teclado Genius ) | S29: DC01-19685
B30: 440000 | I30: ABBA 172 | J30: 23359505 | L30: 1061793315 | M30: =VLOOKUP(L30,#REF!,2,0) -> #REF! | N30: =VLOOKUP(L30,#REF!,3,0) -> #REF! | O30: =VLOOKUP(L30,#REF!,4,0) -> #REF! | P30: =VLOOKUP(L30,#REF!,5,0) -> #REF! | Q30: Factura Abba 172 Compra De Lona Para La Foton Del Promocional Mes De Junio Solicitud De Mercadeo | S30: DC01-19675
B31: 444538 | I31: Fve 5277 | J31: 23359505 | L31: 900434234 | M31: =VLOOKUP(L31,#REF!,2,0) -> #REF! | N31: =VLOOKUP(L31,#REF!,3,0) -> #REF! | O31: =VLOOKUP(L31,#REF!,4,0) -> #REF! | P31: =VLOOKUP(L31,#REF!,5,0) -> #REF! | Q31: Factura Fve 5277 Oficauca Sas, Alquiler De Fotocopiadora Area De Archivo De 18 De Junio Al 18 De Julio 2024 - Factura Fve 5278 Oficauca Sas, Alquiler De Fotocopiadora Sede San Agustin De 15 De Junio Al 15 De Julio 2024 | S31: DC01-19673
B32: 230000 | I32: Fe 1619 | J32: 23359505 | L32: 900375592 | M32: =VLOOKUP(L32,#REF!,2,0) -> #REF! | N32: =VLOOKUP(L32,#REF!,3,0) -> #REF! | O32: =VLOOKUP(L32,#REF!,4,0) -> #REF! | P32: =VLOOKUP(L32,#REF!,5,0) -> #REF! | Q32: Factura Fe 1619 Servicio De Reparacion Caja Fuerte De Of Principal De Puerto | S32: DC01-19677
B33: 1189750 | I33: MKM 2325 | J33: 23359505 | L33: 900796527 | M33: =VLOOKUP(L33,#REF!,2,0) -> #REF! | N33: =VLOOKUP(L33,#REF!,3,0) -> #REF! | O33: =VLOOKUP(L33,#REF!,4,0) -> #REF! | P33: =VLOOKUP(L33,#REF!,5,0) -> #REF! | Q33: Factura Mkm 2325 Serivicio De Instalacion De Biometrico En Oficina De Unicentro Y Suministro De Boton Y Terminal De Reconocimiento Facial | S33: DC01-19725
B34: =170000+376000 -> 546000 | J34: 23359505 | L34: 4758926 | M34: =VLOOKUP(L34,#REF!,2,0) -> #REF! | N34: =VLOOKUP(L34,#REF!,3,0) -> #REF! | O34: =VLOOKUP(L34,#REF!,4,0) -> #REF! | P34: =VLOOKUP(L34,#REF!,5,0) -> #REF! | Q34: CUENTA DE COBRO COMPRA DE BASE PARA TOMBOLA SOLICITUD AREA DE MERCADEO CUENTA DE COBRO SERVICIO DE ARREGLOS (CAJA DE SEGURIDAD OFI PRINICPAL, ARREGLO MANIJAS DE CAJA DE SEGURIDAD Y SOLDADURA DE PUERTA QUE CONDUCE AL CIELO RASO DE LA OFICINA PRINCIPAL | S34: DSEF-2583-2587
B35: =3290000+220000+564000 -> 4074000 | I35: 178-179-180 | J35: 23359505 | L35: 10489352 | M35: =VLOOKUP(L35,#REF!,2,0) -> #REF! | N35: =VLOOKUP(L35,#REF!,3,0) -> #REF! | O35: =VLOOKUP(L35,#REF!,4,0) -> #REF! | P35: =VLOOKUP(L35,#REF!,5,0) -> #REF! | Q35: cuenta de cobro 178 INTERVENTOR?A EL?CTRICA A OF PRINCIPAL DE SANTANDER cuenta de cobro 179 SERVICIO DE ADECUACION ELECTRICA Y CABLEADO HDMI EN OFICINA SALA DE JUNTAS DE LA OFICINA PRINCIPAL DE SANTANDER cuenta de cobro 180 SERVICIO DE MANTENIMIENTO EL?CTRICO EN OFICINA PALACIO DEL PANDEBONO | S35: DSEF-2585-2586-2594
B36: 686200 | J36: 23359505 | L36: 10593556 | M36: =VLOOKUP(L36,#REF!,2,0) -> #REF! | N36: =VLOOKUP(L36,#REF!,3,0) -> #REF! | O36: =VLOOKUP(L36,#REF!,4,0) -> #REF! | P36: =VLOOKUP(L36,#REF!,5,0) -> #REF! | Q36: cuentas de cobro SERVICIO DE PAUTA PUBLICITARIA MERCADERES, MES DE mayo y junio | S36: DSEF-2588
B37: 96000 | J37: 23359505 | L37: 1152699645 | M37: =VLOOKUP(L37,#REF!,2,0) -> #REF! | N37: =VLOOKUP(L37,#REF!,3,0) -> #REF! | O37: =VLOOKUP(L37,#REF!,4,0) -> #REF! | P37: =VLOOKUP(L37,#REF!,5,0) -> #REF! | Q37: factura 1261 y 1262 servicio de hospedaje para los colaboradores Claudia Carabali la noche del 20 de junio de 2024 y Andres Vasquez las noches del 18 y 19 de junio de 2024 | S37: DSEF-2589
B38: 1350000 | I38: 522 | J38: 23359505 | L38: 1062286671 | M38: =VLOOKUP(L38,#REF!,2,0) -> #REF! | N38: =VLOOKUP(L38,#REF!,3,0) -> #REF! | O38: =VLOOKUP(L38,#REF!,4,0) -> #REF! | P38: =VLOOKUP(L38,#REF!,5,0) -> #REF! | Q38: cuenta de cobro 522 Concepto De Valla Publicitaria De 4*8 Metros Ubicada En Hacienda Los Potrillos En Santander De Quilichao, Pauta Publicitaria En Tv, Difunsion En Redes Sociales, Cubrimientos Noticiosos Y Registro Fotografico Mes junio 2024 | S38: DSEF-2593
B39: 235000 | I39: 464 | J39: 23359505 | L39: 10306164 | M39: =VLOOKUP(L39,#REF!,2,0) -> #REF! | N39: =VLOOKUP(L39,#REF!,3,0) -> #REF! | O39: =VLOOKUP(L39,#REF!,4,0) -> #REF! | P39: =VLOOKUP(L39,#REF!,5,0) -> #REF! | Q39: factura 464 GLPI 80140 SERVICIO DE MANTENIMIENTO A CORTINA PV PALACE. | S39: DSEF-2597
B40: 140000 | J40: 23359505 | L40: 34326739 | M40: =VLOOKUP(L40,#REF!,2,0) -> #REF! | N40: =VLOOKUP(L40,#REF!,3,0) -> #REF! | O40: =VLOOKUP(L40,#REF!,4,0) -> #REF! | P40: =VLOOKUP(L40,#REF!,5,0) -> #REF! | Q40: cuenta de cobro GLPI 80725 SERVICIO DE TRANSPORTE EN LA ZONA DE POPAY?N (4 VIAJES ) transporte de marcotensor y tombola, trasnporte monserreat evento mercadeo, transporte escombros bodega creciendo, transporte terminal de trasnporte | S40: DSEF-2596
B41: 799000 | J41: 23359505 | L41: 10386119 | M41: =VLOOKUP(L41,#REF!,2,0) -> #REF! | N41: =VLOOKUP(L41,#REF!,3,0) -> #REF! | O41: =VLOOKUP(L41,#REF!,4,0) -> #REF! | P41: =VLOOKUP(L41,#REF!,5,0) -> #REF! | Q41: cuenta de cobro EXPANSI?N, TRASLADO DE PUERTA DE SEGURIDAD, ESTUCO Y PINTURA MANO DE OBRA EN EXPANSI?N OF LA BARCA, GUAPI | S41: DSEF-2595
...
